<mujoco model="Humanoid">

	<compiler angle="radian" meshdir="../meshes" />
	<compiler inertiafromgeom = "false" angle = "radian" />
	<option timestep = "0.001" iterations = "50" tolerance = "1e-10" jacobian = "dense" cone = "pyramidal" gravity = "0.0 0.0 -9.8" solver = "Newton" impratio = "50" />
	<size nconmax = "1000" njmax = "1000" nuserdata="1000" nuser_actuator="34"/>

	<visual>
		<map force = "0.025" zfar = "30"/>
		<rgba haze = "0.15 0.25 0.35 1" com = "1.0 0.1 0.1 1"/>
		<quality shadowsize = "2048"/>
		<global offwidth = "800" offheight = "800" fovy = "45" linewidth = "0.1"/>
		<scale forcewidth = "0.05" contactwidth = "0.1" com = "0.2"/>
	</visual>

	<asset>
		<mesh name = "trunk"       file = "trunk.STL" />
		<mesh name = "arm_left"    file = "arm_left.STL" />
		<mesh name = "arm_right"   file = "arm_right.STL" />
		<mesh name = "hip_left"    file = "hip_left.STL" />
		<mesh name = "thigh_left"  file = "thigh_left.STL" />
		<mesh name = "calf_left"   file = "calf_left.STL" />
		<mesh name = "foot_left"   file = "foot_left.STL" />
		<mesh name = "hip_right"   file = "hip_right.STL" />
		<mesh name = "thigh_right" file = "thigh_right.STL" />
		<mesh name = "calf_right"	 file = "calf_right.STL" />
		<mesh name = "foot_right"  file = "foot_right.STL" />
		<mesh name = "convex_trunk" file = "trunk.STL" />
		<texture name = "texplane"   type = "2d" builtin = "checker" rgb1 = ".2 .3 .4" rgb2 = ".1 0.15 0.2" width = "512" height = "512" mark = "cross" markrgb = ".8 .8 .8" />
		<texture name = "texgeom" type = "cube" builtin = "flat" mark = "cross" width = "127" height = "1278" rgb1 = "0.8 0.6 0.4" rgb2 = "0.8 0.6 0.4" markrgb = "1 1 1" random = "0.01" />
		<material name = "matplane" reflectance = "0.3" texture = "texplane" texrepeat = "1 1" texuniform = "true" />
		<material name = "matgeom" texture = "texgeom" texuniform = "true" rgba = "0.8 0.6 .4 1" />
	</asset>

	<worldbody>
		<geom name = "floor" pos = "0 0 0" size = "0 0 .25" type = "plane" material = "matplane" solref = "0.002 0.000001" friction = "2.5 0.5 0.0001" condim = "3"/>

		<light directional = "false" diffuse = ".2 .2 .2" specular = "0 0 0" pos = "0 0 5" dir = "0 0 -1" castshadow = "false"/>
		<light mode = "targetbodycom" target = "trunk" directional = "false" diffuse = ".8 .8 .8" specular = "0.3 0.3 0.3" pos = "0 0 4.0" dir = "0 0 -1"/>

		<body name = "trunk" pos = "0 0 1.35000000">
			<inertial pos = "0 0 -0.2" mass = "24.56000000" diaginertia = "1.07690000 0.61810000 0.50336000"/>
			<freejoint name = "root"/>
			<geom type="mesh" pos = "0 0 -0.17" contype="0" conaffinity="0" group="1" rgba="0.898039 0.917647 0.929412 1" mesh="trunk" />
			<geom type="mesh" pos = "0 0 -0.17" rgba="0.898039 0.917647 0.929412 1" mesh="trunk" />
			<site name = "imu" size = "0.01" pos = "0 0 0.1"/>
			<body name = "hip_right" pos = "0.00000000 -0.10000000 -0.37000000">
				<inertial pos = "0 0 0" mass = "1.00000000" diaginertia = "0.02289200 0.02802500 0.02802500"/>
				<joint name = "hip_right_x" type="hinge" pos = "0.00000000 0.00000000 0.00000000" axis = "-1 0 0" range = "-0.26179939 0.26179939" limited = "true" armature = "0.15" frictionloss = "0.00"/>
				<geom type="mesh" contype="0" conaffinity="0" group="1" rgba="0.898039 0.917647 0.929412 1" mesh="hip_right" />
				<body name = "thigh_right" pos = "0.00000000 0.00000000 0.00000000">
					<inertial pos = "-0.00000000 -0.00000000 -0.21100000" mass = "3.32000000" diaginertia = "0.04289200 0.04802500 0.01078400"/>
					<joint name = "hip_right_y" type="hinge" pos = "0.00000000 0.00000000 0.00000000" axis = "0 -1 0" range = "-0.61086524 1.74532925" limited = "true" armature = "0.15" frictionloss = "0.00"/>
					<geom type="mesh" contype="0" conaffinity="0" group="1" rgba="0.898039 0.917647 0.929412 1" mesh="thigh_right" />
					<body name = "calf_right" pos = "0.00000000 0.00000000 -0.45000000">
						<inertial pos = "-0.00000000 -0.00000000 -0.23000000" mass = "3.30000000" diaginertia = "0.06232800 0.06266400 0.00459200"/>
						<joint name = "knee_right" type="hinge" pos = "0.00000000 0.00000000 0.00000000" axis = "0 -1 0" range = "-2.18166156 0.00000000" limited = "true" armature = "0.15" frictionloss = "0.00"/>
						<geom type="mesh" contype="0" conaffinity="0" group="1" rgba="0.898039 0.917647 0.929412 1" mesh="calf_right" />
						<body name = "foot_right" pos = "0.02500000 0.00000000 -0.54000000">
							<inertial pos = "0 0 -0.05" mass = "0.50000000" diaginertia = "0.00082700 0.00082700 0.00080000"/>
							<joint name = "ankle_right_y" type="hinge" pos = "-0.02500000 0.00000000 0.10000000" axis = "0 -1 0" range = "-1.04719755 0.97738438" limited = "true" armature = "0.15" frictionloss = "0.00"/>
							<joint name = "ankle_right_x" type="hinge" pos = "-0.02500000 0.00000000 0.10000000" axis = "-1 0 0" range = "-0.26179939 0.26179939" limited = "true" armature = "0.15" frictionloss = "0.00"/>
							<geom name = "foot_right_geom" type = "box" size = "0.1500000 0.0750000 0.01000000"/>
							<site name="rf_force"  size="0.01" pos="0.05 0.0 0" />
						</body>
					</body>
				</body>
			</body>
			<body name = "hip_left" pos = "0.00000000 0.10000000 -0.37000000">
				<inertial pos = "0 0 0" mass = "1.00000000" diaginertia = "0.02289200 0.02802500 0.02802500"/>
				<joint name = "hip_left_x" type="hinge" pos = "0.00000000 0.00000000 0.00000000" axis = "-1 0 0" range = "-0.26179939 0.26179939" limited = "true" armature = "0.15" frictionloss = "0.00"/>
				<geom type="mesh" contype="0" conaffinity="0" group="1" rgba="0.898039 0.917647 0.929412 1" mesh="hip_left" />
				<body name = "thigh_left" pos = "0.00000000 0.00000000 0.00000000">
					<inertial pos = "-0.00000000 -0.00000000 -0.21100000" mass = "3.32000000" diaginertia = "0.04289200 0.04802500 0.01078400"/>
					<joint name = "hip_left_y" type="hinge" pos = "0.00000000 0.00000000 0.00000000" axis = "0 -1 0" range = "-0.61086524 1.74532925" limited = "true" armature = "0.15" frictionloss = "0.00"/>
					<geom type="mesh" contype="0" conaffinity="0" group="1" rgba="0.898039 0.917647 0.929412 1" mesh="thigh_left" />
					<body name = "calf_left" pos = "0.00000000 0.00000000 -0.45000000">
						<inertial pos = "-0.00000000 -0.00000000 -0.23000000" mass = "3.30000000" diaginertia = "0.06232800 0.06266400 0.00459200"/>
						<joint name = "knee_left" type="hinge" pos = "0.00000000 0.00000000 0.00000000" axis = "0 -1 0" range = "-2.18166156 0.00000000" limited = "true" armature = "0.15" frictionloss = "0.00"/>
						<geom type="mesh" contype="0" conaffinity="0" group="1" rgba="0.898039 0.917647 0.929412 1" mesh="calf_left" />
						<body name = "foot_left" pos = "0.02500000 0.00000000 -0.54000000">
							<inertial pos = "0 0 -0.05" mass = "0.50000000" diaginertia = "0.00082700 0.00082700 0.00080000"/>
							<joint name = "ankle_left_y" type="hinge" pos = "-0.02500000 0.00000000 0.10000000" axis = "0 -1 0" range = "-1.04719755 0.97738438" limited = "true" armature = "0.15" frictionloss = "0.00"/>
							<joint name = "ankle_left_x" type="hinge" pos = "-0.02500000 0.00000000 0.10000000" axis = "-1 0 0" range = "-0.26179939 0.26179939" limited = "true" armature = "0.15" frictionloss = "0.00"/>
							<geom name = "foot_left_geom" type = "box" size = "0.1500000 0.075000 0.01000000"/>
							<site name="lf_force"  size="0.01" pos="0.05 0.0 0" />
						</body>
					</body>
				</body>
			</body>
			<body name = "arm_right" pos = "0.00000000 -0.25000000 -0.02000000">
				<joint name = "shoulder_right" type="hinge" pos = "0.00000000 0.00000000 0.00000000" axis = "0 -1 0" range = "-3.14159265 3.14159265" limited = "true" armature = "0.15" frictionloss = "0.00"/>
				<inertial pos = "0 0 -0.25" mass = "2.00000000" diaginertia = "0.07912400 0.06317300 0.02063900"/>
				<geom type="mesh" contype="0" conaffinity="0" group="1" rgba="0.898039 0.917647 0.929412 1" mesh="arm_right" />
			</body>
			<body name = "arm_left" pos = "0.00000000 0.25000000 -0.02000000">
				<joint name = "shoulder_left" type="hinge" pos = "0.00000000 0.00000000 0.00000000" axis = "0 -1 0" range = "-3.14159265 3.14159265" limited = "true" armature = "0.15" frictionloss = "0.00"/>
				<inertial pos = "0 0 -0.25" mass = "2.00000000" diaginertia = "0.07912400 0.06317300 0.02063900"/>
				<geom type="mesh" contype="0" conaffinity="0" group="1" rgba="0.898039 0.917647 0.929412 1" mesh="arm_left" />
			</body>
		</body>
	</worldbody>

	<contact>
		<exclude body1 = "trunk" body2 = "arm_left" />
		<exclude body1 = "trunk" body2 = "arm_right" />
		<exclude body1 = "trunk" body2 = "hip_left" />
		<exclude body1 = "trunk" body2 = "thigh_left" />
		<exclude body1 = "trunk" body2 = "calf_left" />
		<exclude body1 = "trunk" body2 = "foot_left" />
		<exclude body1 = "trunk" body2 = "hip_right" />
		<exclude body1 = "trunk" body2 = "thigh_right" />
		<exclude body1 = "trunk" body2 = "calf_right" />
		<exclude body1 = "trunk" body2 = "foot_right" />
		<exclude body1 = "arm_left" body2 = "trunk" />
		<exclude body1 = "arm_left" body2 = "arm_right" />
		<exclude body1 = "arm_left" body2 = "hip_left" />
		<exclude body1 = "arm_left" body2 = "thigh_left" />
		<exclude body1 = "arm_left" body2 = "calf_left" />
		<exclude body1 = "arm_left" body2 = "foot_left" />
		<exclude body1 = "arm_left" body2 = "hip_right" />
		<exclude body1 = "arm_left" body2 = "thigh_right" />
		<exclude body1 = "arm_left" body2 = "calf_right" />
		<exclude body1 = "arm_left" body2 = "foot_right" />
		<exclude body1 = "arm_right" body2 = "trunk" />
		<exclude body1 = "arm_right" body2 = "arm_left" />
		<exclude body1 = "arm_right" body2 = "hip_left" />
		<exclude body1 = "arm_right" body2 = "thigh_left" />
		<exclude body1 = "arm_right" body2 = "calf_left" />
		<exclude body1 = "arm_right" body2 = "foot_left" />
		<exclude body1 = "arm_right" body2 = "hip_right" />
		<exclude body1 = "arm_right" body2 = "thigh_right" />
		<exclude body1 = "arm_right" body2 = "calf_right" />
		<exclude body1 = "arm_right" body2 = "foot_right" />
		<exclude body1 = "hip_left" body2 = "trunk" />
		<exclude body1 = "hip_left" body2 = "arm_left" />
		<exclude body1 = "hip_left" body2 = "arm_right" />
		<exclude body1 = "hip_left" body2 = "thigh_left" />
		<exclude body1 = "hip_left" body2 = "calf_left" />
		<exclude body1 = "hip_left" body2 = "foot_left" />
		<exclude body1 = "hip_left" body2 = "hip_right" />
		<exclude body1 = "hip_left" body2 = "thigh_right" />
		<exclude body1 = "hip_left" body2 = "calf_right" />
		<exclude body1 = "hip_left" body2 = "foot_right" />
		<exclude body1 = "thigh_left" body2 = "trunk" />
		<exclude body1 = "thigh_left" body2 = "arm_left" />
		<exclude body1 = "thigh_left" body2 = "arm_right" />
		<exclude body1 = "thigh_left" body2 = "hip_left" />
		<exclude body1 = "thigh_left" body2 = "calf_left" />
		<exclude body1 = "thigh_left" body2 = "foot_left" />
		<exclude body1 = "thigh_left" body2 = "hip_right" />
		<exclude body1 = "thigh_left" body2 = "thigh_right" />
		<exclude body1 = "thigh_left" body2 = "calf_right" />
		<exclude body1 = "thigh_left" body2 = "foot_right" />
		<exclude body1 = "calf_left" body2 = "trunk" />
		<exclude body1 = "calf_left" body2 = "arm_left" />
		<exclude body1 = "calf_left" body2 = "arm_right" />
		<exclude body1 = "calf_left" body2 = "hip_left" />
		<exclude body1 = "calf_left" body2 = "thigh_left" />
		<exclude body1 = "calf_left" body2 = "foot_left" />
		<exclude body1 = "calf_left" body2 = "hip_right" />
		<exclude body1 = "calf_left" body2 = "thigh_right" />
		<exclude body1 = "calf_left" body2 = "calf_right" />
		<exclude body1 = "calf_left" body2 = "foot_right" />
		<exclude body1 = "foot_left" body2 = "trunk" />
		<exclude body1 = "foot_left" body2 = "arm_left" />
		<exclude body1 = "foot_left" body2 = "arm_right" />
		<exclude body1 = "foot_left" body2 = "hip_left" />
		<exclude body1 = "foot_left" body2 = "thigh_left" />
		<exclude body1 = "foot_left" body2 = "calf_left" />
		<exclude body1 = "foot_left" body2 = "hip_right" />
		<exclude body1 = "foot_left" body2 = "thigh_right" />
		<exclude body1 = "foot_left" body2 = "calf_right" />
		<exclude body1 = "foot_left" body2 = "foot_right" />
		<exclude body1 = "hip_right" body2 = "trunk" />
		<exclude body1 = "hip_right" body2 = "arm_left" />
		<exclude body1 = "hip_right" body2 = "arm_right" />
		<exclude body1 = "hip_right" body2 = "hip_left" />
		<exclude body1 = "hip_right" body2 = "thigh_left" />
		<exclude body1 = "hip_right" body2 = "calf_left" />
		<exclude body1 = "hip_right" body2 = "foot_left" />
		<exclude body1 = "hip_right" body2 = "thigh_right" />
		<exclude body1 = "hip_right" body2 = "calf_right" />
		<exclude body1 = "hip_right" body2 = "foot_right" />
		<exclude body1 = "thigh_right" body2 = "trunk" />
		<exclude body1 = "thigh_right" body2 = "arm_left" />
		<exclude body1 = "thigh_right" body2 = "arm_right" />
		<exclude body1 = "thigh_right" body2 = "hip_left" />
		<exclude body1 = "thigh_right" body2 = "thigh_left" />
		<exclude body1 = "thigh_right" body2 = "calf_left" />
		<exclude body1 = "thigh_right" body2 = "foot_left" />
		<exclude body1 = "thigh_right" body2 = "hip_right" />
		<exclude body1 = "thigh_right" body2 = "calf_right" />
		<exclude body1 = "thigh_right" body2 = "foot_right" />
		<exclude body1 = "calf_right" body2 = "trunk" />
		<exclude body1 = "calf_right" body2 = "arm_left" />
		<exclude body1 = "calf_right" body2 = "arm_right" />
		<exclude body1 = "calf_right" body2 = "hip_left" />
		<exclude body1 = "calf_right" body2 = "thigh_left" />
		<exclude body1 = "calf_right" body2 = "calf_left" />
		<exclude body1 = "calf_right" body2 = "foot_left" />
		<exclude body1 = "calf_right" body2 = "hip_right" />
		<exclude body1 = "calf_right" body2 = "thigh_right" />
		<exclude body1 = "calf_right" body2 = "foot_right" />
		<exclude body1 = "foot_right" body2 = "trunk" />
		<exclude body1 = "foot_right" body2 = "arm_left" />
		<exclude body1 = "foot_right" body2 = "arm_right" />
		<exclude body1 = "foot_right" body2 = "hip_left" />
		<exclude body1 = "foot_right" body2 = "thigh_left" />
		<exclude body1 = "foot_right" body2 = "calf_left" />
		<exclude body1 = "foot_right" body2 = "foot_left" />
		<exclude body1 = "foot_right" body2 = "hip_right" />
		<exclude body1 = "foot_right" body2 = "thigh_right" />
		<exclude body1 = "foot_right" body2 = "calf_right" />
	</contact>
	<sensor>
		<force         name="rf_fsensor"    site="rf_force" />
		<torque        name="rf_tsensor"    site="rf_force" />
		<force         name="lf_fsensor"    site="lf_force" />
		<torque        name="lf_tsensor"    site="lf_force" />
		<gyro		   name="root_gyro"	  site="imu" />
		<accelerometer name="root_accel"	  site="imu" />
	</sensor>
	<actuator>
		<motor name="shoulder_left" joint="shoulder_left" />
		<motor name="shoulder_right" joint="shoulder_right" />
		<motor name="knee_left" joint="knee_left" />
		<motor name="hip_left_x" joint="hip_left_x" />
		<motor name="hip_left_y" joint="hip_left_y" />
		<motor name="ankle_left_y" joint="ankle_left_y" />
		<motor name="ankle_left_x" joint="ankle_left_x" />
		<motor name="knee_right" joint="knee_right" />
		<motor name="hip_right_x" joint="hip_right_x" />
		<motor name="hip_right_y" joint="hip_right_y" />
		<motor name="ankle_right_y" joint="ankle_right_y" />
		<motor name="ankle_right_x" joint="ankle_right_x" />
	</actuator>


</mujoco>
